2023-01-11 15:02:12,046 ERROR: Exception on /multiplayer/lobby/ [GET] [in /Users/durness/Documents/Coding/GitHub/arcade/venv/lib/python3.10/site-packages/flask/app.py:1741]
Traceback (most recent call last):
  File "/Users/durness/Documents/Coding/GitHub/arcade/venv/lib/python3.10/site-packages/flask/app.py", line 2525, in wsgi_app
    response = self.full_dispatch_request()
  File "/Users/durness/Documents/Coding/GitHub/arcade/venv/lib/python3.10/site-packages/flask/app.py", line 1822, in full_dispatch_request
    rv = self.handle_user_exception(e)
  File "/Users/durness/Documents/Coding/GitHub/arcade/venv/lib/python3.10/site-packages/flask/app.py", line 1820, in full_dispatch_request
    rv = self.dispatch_request()
  File "/Users/durness/Documents/Coding/GitHub/arcade/venv/lib/python3.10/site-packages/flask/app.py", line 1796, in dispatch_request
    return self.ensure_sync(self.view_functions[rule.endpoint])(**view_args)
  File "/Users/durness/Documents/Coding/GitHub/arcade/venv/lib/python3.10/site-packages/flask_login/utils.py", line 290, in decorated_view
    return current_app.ensure_sync(func)(*args, **kwargs)
  File "/Users/durness/Documents/Coding/GitHub/arcade/arcade_app/game/routes.py", line 28, in multiplayer_lobby
    players = db.session.query(ActiveUsers).filter_by(lobby_id=session.get('lobby_id')).scalars().all()
AttributeError: 'Query' object has no attribute 'scalars'
2023-01-11 15:02:36,862 INFO: Arcade startup [in /Users/durness/Documents/Coding/GitHub/arcade/arcade_app/__init__.py:52]
2023-01-11 15:02:43,843 ERROR: Exception on /multiplayer/lobby/ [GET] [in /Users/durness/Documents/Coding/GitHub/arcade/venv/lib/python3.10/site-packages/flask/app.py:1741]
Traceback (most recent call last):
  File "/Users/durness/Documents/Coding/GitHub/arcade/venv/lib/python3.10/site-packages/flask/app.py", line 2525, in wsgi_app
    response = self.full_dispatch_request()
  File "/Users/durness/Documents/Coding/GitHub/arcade/venv/lib/python3.10/site-packages/flask/app.py", line 1822, in full_dispatch_request
    rv = self.handle_user_exception(e)
  File "/Users/durness/Documents/Coding/GitHub/arcade/venv/lib/python3.10/site-packages/flask/app.py", line 1820, in full_dispatch_request
    rv = self.dispatch_request()
  File "/Users/durness/Documents/Coding/GitHub/arcade/venv/lib/python3.10/site-packages/flask/app.py", line 1796, in dispatch_request
    return self.ensure_sync(self.view_functions[rule.endpoint])(**view_args)
  File "/Users/durness/Documents/Coding/GitHub/arcade/venv/lib/python3.10/site-packages/flask_login/utils.py", line 290, in decorated_view
    return current_app.ensure_sync(func)(*args, **kwargs)
  File "/Users/durness/Documents/Coding/GitHub/arcade/arcade_app/game/routes.py", line 28, in multiplayer_lobby
    players = db.session.execute(ActiveUsers).filter_by(lobby_id=session.get('lobby_id')).scalars().all()
  File "<string>", line 2, in execute
  File "/Users/durness/Documents/Coding/GitHub/arcade/venv/lib/python3.10/site-packages/sqlalchemy/orm/session.py", line 1628, in execute
    statement = coercions.expect(roles.StatementRole, statement)
  File "/Users/durness/Documents/Coding/GitHub/arcade/venv/lib/python3.10/site-packages/sqlalchemy/sql/coercions.py", line 188, in expect
    resolved = impl._literal_coercion(
  File "/Users/durness/Documents/Coding/GitHub/arcade/venv/lib/python3.10/site-packages/sqlalchemy/sql/coercions.py", line 401, in _literal_coercion
    self._raise_for_expected(element, argname)
  File "/Users/durness/Documents/Coding/GitHub/arcade/venv/lib/python3.10/site-packages/sqlalchemy/sql/coercions.py", line 283, in _raise_for_expected
    util.raise_(exc.ArgumentError(msg, code=code), replace_context=err)
  File "/Users/durness/Documents/Coding/GitHub/arcade/venv/lib/python3.10/site-packages/sqlalchemy/util/compat.py", line 210, in raise_
    raise exception
sqlalchemy.exc.ArgumentError: Executable SQL or text() construct expected, got <class 'arcade_app.models.ActiveUsers'>.
2023-01-11 15:03:18,835 INFO: Arcade startup [in /Users/durness/Documents/Coding/GitHub/arcade/arcade_app/__init__.py:52]
