2022-12-27 15:01:56,809 ERROR: Exception on /highscores [POST] [in /Users/durness/Documents/Coding/GitHub/arcade/venv/lib/python3.10/site-packages/flask/app.py:1741]
Traceback (most recent call last):
  File "/Users/durness/Documents/Coding/GitHub/arcade/venv/lib/python3.10/site-packages/flask/app.py", line 2525, in wsgi_app
    response = self.full_dispatch_request()
  File "/Users/durness/Documents/Coding/GitHub/arcade/venv/lib/python3.10/site-packages/flask/app.py", line 1822, in full_dispatch_request
    rv = self.handle_user_exception(e)
  File "/Users/durness/Documents/Coding/GitHub/arcade/venv/lib/python3.10/site-packages/flask/app.py", line 1820, in full_dispatch_request
    rv = self.dispatch_request()
  File "/Users/durness/Documents/Coding/GitHub/arcade/venv/lib/python3.10/site-packages/flask/app.py", line 1796, in dispatch_request
    return self.ensure_sync(self.view_functions[rule.endpoint])(**view_args)
  File "/Users/durness/Documents/Coding/GitHub/arcade/venv/lib/python3.10/site-packages/flask_login/utils.py", line 290, in decorated_view
    return current_app.ensure_sync(func)(*args, **kwargs)
  File "/Users/durness/Documents/Coding/GitHub/arcade/arcade_app/main/routes.py", line 85, in highscores
    s = Score(current_user, score=content['score'])
TypeError: __init__() takes 1 positional argument but 2 were given
2022-12-27 15:04:21,621 INFO: Arcade startup [in /Users/durness/Documents/Coding/GitHub/arcade/arcade_app/__init__.py:47]
2022-12-27 15:04:36,490 ERROR: Exception on /highscores [POST] [in /Users/durness/Documents/Coding/GitHub/arcade/venv/lib/python3.10/site-packages/flask/app.py:1741]
Traceback (most recent call last):
  File "/Users/durness/Documents/Coding/GitHub/arcade/venv/lib/python3.10/site-packages/flask/app.py", line 2525, in wsgi_app
    response = self.full_dispatch_request()
  File "/Users/durness/Documents/Coding/GitHub/arcade/venv/lib/python3.10/site-packages/flask/app.py", line 1822, in full_dispatch_request
    rv = self.handle_user_exception(e)
  File "/Users/durness/Documents/Coding/GitHub/arcade/venv/lib/python3.10/site-packages/flask/app.py", line 1820, in full_dispatch_request
    rv = self.dispatch_request()
  File "/Users/durness/Documents/Coding/GitHub/arcade/venv/lib/python3.10/site-packages/flask/app.py", line 1796, in dispatch_request
    return self.ensure_sync(self.view_functions[rule.endpoint])(**view_args)
  File "/Users/durness/Documents/Coding/GitHub/arcade/venv/lib/python3.10/site-packages/flask_login/utils.py", line 290, in decorated_view
    return current_app.ensure_sync(func)(*args, **kwargs)
  File "/Users/durness/Documents/Coding/GitHub/arcade/arcade_app/main/routes.py", line 85, in highscores
    s = Score(current_user.id, score=content['score'])
TypeError: __init__() takes 1 positional argument but 2 were given
2022-12-27 15:05:15,552 INFO: Arcade startup [in /Users/durness/Documents/Coding/GitHub/arcade/arcade_app/__init__.py:47]
2022-12-27 15:05:18,595 ERROR: Exception on /highscores [POST] [in /Users/durness/Documents/Coding/GitHub/arcade/venv/lib/python3.10/site-packages/flask/app.py:1741]
Traceback (most recent call last):
  File "/Users/durness/Documents/Coding/GitHub/arcade/venv/lib/python3.10/site-packages/flask/app.py", line 2525, in wsgi_app
    response = self.full_dispatch_request()
  File "/Users/durness/Documents/Coding/GitHub/arcade/venv/lib/python3.10/site-packages/flask/app.py", line 1822, in full_dispatch_request
    rv = self.handle_user_exception(e)
  File "/Users/durness/Documents/Coding/GitHub/arcade/venv/lib/python3.10/site-packages/flask/app.py", line 1820, in full_dispatch_request
    rv = self.dispatch_request()
  File "/Users/durness/Documents/Coding/GitHub/arcade/venv/lib/python3.10/site-packages/flask/app.py", line 1796, in dispatch_request
    return self.ensure_sync(self.view_functions[rule.endpoint])(**view_args)
  File "/Users/durness/Documents/Coding/GitHub/arcade/venv/lib/python3.10/site-packages/flask_login/utils.py", line 290, in decorated_view
    return current_app.ensure_sync(func)(*args, **kwargs)
  File "/Users/durness/Documents/Coding/GitHub/arcade/arcade_app/main/routes.py", line 86, in highscores
    s = Score(current_user.id, score=content['score'])
TypeError: __init__() takes 1 positional argument but 2 were given
2022-12-27 15:06:37,594 INFO: Arcade startup [in /Users/durness/Documents/Coding/GitHub/arcade/arcade_app/__init__.py:47]
2022-12-27 15:07:43,609 INFO: Arcade startup [in /Users/durness/Documents/Coding/GitHub/arcade/arcade_app/__init__.py:47]
2022-12-27 15:08:53,511 INFO: Arcade startup [in /Users/durness/Documents/Coding/GitHub/arcade/arcade_app/__init__.py:47]
2022-12-27 15:10:37,244 INFO: Arcade startup [in /Users/durness/Documents/Coding/GitHub/arcade/arcade_app/__init__.py:47]
2022-12-27 15:13:26,251 INFO: Arcade startup [in /Users/durness/Documents/Coding/GitHub/arcade/arcade_app/__init__.py:47]
2022-12-27 15:17:03,696 INFO: Arcade startup [in /Users/durness/Documents/Coding/GitHub/arcade/arcade_app/__init__.py:47]
2022-12-27 15:18:11,691 INFO: Arcade startup [in /Users/durness/Documents/Coding/GitHub/arcade/arcade_app/__init__.py:47]
2022-12-27 15:19:43,000 INFO: Arcade startup [in /Users/durness/Documents/Coding/GitHub/arcade/arcade_app/__init__.py:47]
2022-12-27 15:19:45,287 ERROR: Exception on /gameover [GET] [in /Users/durness/Documents/Coding/GitHub/arcade/venv/lib/python3.10/site-packages/flask/app.py:1741]
Traceback (most recent call last):
  File "/Users/durness/Documents/Coding/GitHub/arcade/venv/lib/python3.10/site-packages/flask/app.py", line 2525, in wsgi_app
    response = self.full_dispatch_request()
  File "/Users/durness/Documents/Coding/GitHub/arcade/venv/lib/python3.10/site-packages/flask/app.py", line 1822, in full_dispatch_request
    rv = self.handle_user_exception(e)
  File "/Users/durness/Documents/Coding/GitHub/arcade/venv/lib/python3.10/site-packages/flask/app.py", line 1820, in full_dispatch_request
    rv = self.dispatch_request()
  File "/Users/durness/Documents/Coding/GitHub/arcade/venv/lib/python3.10/site-packages/flask/app.py", line 1796, in dispatch_request
    return self.ensure_sync(self.view_functions[rule.endpoint])(**view_args)
  File "/Users/durness/Documents/Coding/GitHub/arcade/venv/lib/python3.10/site-packages/flask_login/utils.py", line 290, in decorated_view
    return current_app.ensure_sync(func)(*args, **kwargs)
  File "/Users/durness/Documents/Coding/GitHub/arcade/arcade_app/main/routes.py", line 70, in gameover
    return redirect(url_for('gameover'))
  File "/Users/durness/Documents/Coding/GitHub/arcade/venv/lib/python3.10/site-packages/flask/helpers.py", line 256, in url_for
    return current_app.url_for(
  File "/Users/durness/Documents/Coding/GitHub/arcade/venv/lib/python3.10/site-packages/flask/app.py", line 2031, in url_for
    return self.handle_url_build_error(error, endpoint, values)
  File "/Users/durness/Documents/Coding/GitHub/arcade/venv/lib/python3.10/site-packages/flask/app.py", line 2020, in url_for
    rv = url_adapter.build(  # type: ignore[union-attr]
  File "/Users/durness/Documents/Coding/GitHub/arcade/venv/lib/python3.10/site-packages/werkzeug/routing/map.py", line 917, in build
    raise BuildError(endpoint, values, method, self)
werkzeug.routing.exceptions.BuildError: Could not build url for endpoint 'gameover'. Did you mean 'main.gameover' instead?
2022-12-27 15:19:57,151 INFO: Arcade startup [in /Users/durness/Documents/Coding/GitHub/arcade/arcade_app/__init__.py:47]
2022-12-27 15:20:32,969 INFO: Arcade startup [in /Users/durness/Documents/Coding/GitHub/arcade/arcade_app/__init__.py:47]
2022-12-27 15:20:34,333 ERROR: Exception on /gameover [GET] [in /Users/durness/Documents/Coding/GitHub/arcade/venv/lib/python3.10/site-packages/flask/app.py:1741]
Traceback (most recent call last):
  File "/Users/durness/Documents/Coding/GitHub/arcade/venv/lib/python3.10/site-packages/flask/app.py", line 2525, in wsgi_app
    response = self.full_dispatch_request()
  File "/Users/durness/Documents/Coding/GitHub/arcade/venv/lib/python3.10/site-packages/flask/app.py", line 1822, in full_dispatch_request
    rv = self.handle_user_exception(e)
  File "/Users/durness/Documents/Coding/GitHub/arcade/venv/lib/python3.10/site-packages/flask/app.py", line 1820, in full_dispatch_request
    rv = self.dispatch_request()
  File "/Users/durness/Documents/Coding/GitHub/arcade/venv/lib/python3.10/site-packages/flask/app.py", line 1796, in dispatch_request
    return self.ensure_sync(self.view_functions[rule.endpoint])(**view_args)
  File "/Users/durness/Documents/Coding/GitHub/arcade/venv/lib/python3.10/site-packages/flask_login/utils.py", line 290, in decorated_view
    return current_app.ensure_sync(func)(*args, **kwargs)
  File "/Users/durness/Documents/Coding/GitHub/arcade/arcade_app/main/routes.py", line 70, in gameover
    return render_template('gameover.html')
  File "/Users/durness/Documents/Coding/GitHub/arcade/venv/lib/python3.10/site-packages/flask/templating.py", line 147, in render_template
    return _render(app, template, context)
  File "/Users/durness/Documents/Coding/GitHub/arcade/venv/lib/python3.10/site-packages/flask/templating.py", line 130, in _render
    rv = template.render(context)
  File "/Users/durness/Documents/Coding/GitHub/arcade/venv/lib/python3.10/site-packages/jinja2/environment.py", line 1301, in render
    self.environment.handle_exception()
  File "/Users/durness/Documents/Coding/GitHub/arcade/venv/lib/python3.10/site-packages/jinja2/environment.py", line 936, in handle_exception
    raise rewrite_traceback_stack(source=source)
  File "/Users/durness/Documents/Coding/GitHub/arcade/arcade_app/main/templates/gameover.html", line 1, in top-level template code
    {% extends base.html %}
  File "/Users/durness/Documents/Coding/GitHub/arcade/venv/lib/python3.10/site-packages/jinja2/environment.py", line 485, in getattr
    return getattr(obj, attribute)
jinja2.exceptions.UndefinedError: 'base' is undefined
2022-12-27 15:21:05,486 INFO: Arcade startup [in /Users/durness/Documents/Coding/GitHub/arcade/arcade_app/__init__.py:47]
